Workbook

Sheet 안내
B1: 노사관계 진단·평가 도구 (구글시트용)
B2: 근거: 노사발전재단 「일터혁신 실태조사」 2023·2024·2025 최종보고서 — 일터혁신지수 ‘노사관계’ 영역(100점)
B4: ■ 이 파일은 무엇인가요?
B5: 설문에 답하면 노사발전재단이 매년 발표하는 일터혁신지수 ‘노사관계’ 점수(100점 만점)와 같은 방식으로 자동 채점하고,
B6: 같은 해·같은 조건(규모·업종·노조유무) 사업장 평균과 비교해 등급과 우선 개선과제를 보여줍니다. 매크로 없이 수식만으로 동작합니다.
B7: 쉽게 말하면 — 5과목(분위기·협력/갈등·정보공유·고충처리·노사협의회) 성적표를 만들고 ‘전국 평균 대비 몇 점 위/아래인지’ 알려주는 도구입니다.
B9: ■ 사용 순서
B10: ① [설문] 시트 위쪽 노란 칸에 기관 기본정보(업종·규모·노조·노사협의회·컨설팅 수혜)를 고릅니다.
B11: ② [설문] 시트에서 응답자 1명이 한 열(E열=응답자1, F열=응답자2 …, 최대 50명)을 맡아 드롭다운으로 답합니다.
B12: · 14행 ‘응답자 유형’을 꼭 고르세요(사업주·담당자 / 근로자). 유형을 고르지 않은 열은 집계에서 빠집니다.
B13: · 여러 사람이 동시에 답하려면 구글시트 공유(편집자)로 링크를 보내 각자 자기 열에 입력하면 됩니다.
B14: ③ [결과] 시트에서 응답자 유형·비교연도·비교집단을 고르면 종합점수·등급·벤치마크 비교·우선 개선과제·문항별 강약점이 자동 계산됩니다.
... B24: · 등급(S~D)은 재단 공식 등급이 아니라 이 도구가 정한 ‘벤치마크 대비 차이’ 기준입니다. 자세한 근거는 [모형설계]·[역산검증] 시트에 있습니다.

Sheet 설문
A1: 노사관계 진단 설문
A2: 노란 칸만 입력 · 응답자 1명 = 1열(E열부터 최대 50명) · 드롭다운으로 선택
B4: 기관/사업장명 | D4: 자유 입력
B5: 업종 | C5: 공공행정서비스 | D5: 재단 실태조사 업종 분류
B6: 규모(상시근로자) | C6: 300인 이상 | D6: 벤치마크 규모 구간
B7: 노동조합 | C7: 있음
B8: 노사협의회 | C8: 설치 | D8: 미설치·50인 미만·무노조면 노사협의회 영역 제외 후 100점 환산
B9: 일터혁신 컨설팅(최근 3년) | C9: 받지 않음(일반) | D9: 벤치마크 비교집단 자동 선택에 사용
A12: 문항ID | B12: 구분 | C12: 문항 | D12: 응답 방법 | E12: 응답자1 | F12: 응답자2 | G12: 응답자3 | H12: 응답자4 | I12: 응답자5 | J12: 응답자6 | K12: 응답자7 | L12: 응답자8 | M12: 응답자9 | N12: 응답자10 | O12: 응답자11 | P12: 응답자12 | Q12: 응답자13 | R12: 응답자14 | S12: 응답자15 | T12: 응답자16 | U12: 응답자17 | V12: 응답자18 | W12: 응답자19 | X12: 응답자20 | Y12: 응답자21 | Z12: 응답자22 | AA12: 응답자23 | AB12: 응답자24 | AC12: 응답자25 | AD12: 응답자26 | AE12: 응답자27 | AF12: 응답자28 | AG12: 응답자29 | AH12: 응답자30 | AI12: 응답자31 | AJ12: 응답자32 | AK12: 응답자33 | AL12: 응답자34 | AM12: 응답자35 | AN12: 응답자36 | AO12: 응답자37 | AP12: 응답자38 | AQ12: 응답자39 | AR12: 응답자40 | AS12: 응답자41 | AT12: 응답자42 | AU12: 응답자43 | AV12: 응답자44 | AW12: 응답자45 | AX12: 응답자46 | AY12: 응답자47 | AZ12: 응답자48 | BA12: 응답자49 | BB12: 응답자50
A13: TYPE | C13: 응답자 유형 (반드시 선택) | D13: 사업주·담당자 / 근로자
A14: MEMO | C14: 소속·비고(선택) | D14: 자유 입력
A15: 문16. 노사관계 전반 — 우리 회사는 …
A16: Q16_1 | B16: 노사관계분위기 | C16: 노사의 이해관계가 크게 다르지 않아 협조가 잘 이루어진다 | D16: 1~5 (1 전혀 그렇지 않다 · 3 보통 · 5 매우 그렇다)
A17: Q16_2 | B17: 노사관계분위기 | C17: 노사가 서로 상대방의 일에 대해 반대하지 않는다 | D17: 1~5 (1 전혀 그렇지 않다 · 3 보통 · 5 매우 그렇다)
A18: Q16_3 | B18: 노사관계분위기 | C18: 노사 모두가 회사를 더욱 일하기 좋은 곳으로 만들려고 노력한다 | D18: 1~5 (1 전혀 그렇지 않다 · 3 보통 · 5 매우 그렇다)
A19: Q16_4 | B19: 노사관계분위기 | C19: 그간 노사관계가 협력적이었다 | D19: 1~5 (1 전혀 그렇지 않다 · 3 보통 · 5 매우 그렇다)
A20: 문17. 노사협력 프로그램·행사(최근 3년) — 시행여부, 시행했다면 활성화 정도(1 전혀 활용되지 않음 ~ 5 잘 활용됨)
A21: Q17_1 | B21: 노사협력 및 갈등 | C21: 노사협력선언·노사공동결의대회 — 시행여부 | D21: 시행 / 미시행
A22: Q17_1A | B22: 노사협력 및 갈등 | C22: 노사협력선언·노사공동결의대회 — 활성화 정도(시행한 경우만) | D22: 1~5 (시행한 경우만)
A23: Q17_2 | B23: 노사협력 및 갈등 | C23: 노사공동기구·위원회를 통한 문제해결 — 시행여부 | D23: 시행 / 미시행
A24: Q17_2A | B24: 노사협력 및 갈등 | C24: 노사공동기구·위원회를 통한 문제해결 — 활성화 정도(시행한 경우만) | D24: 1~5 (시행한 경우만)
A25: Q17_3 | B25: 노사협력 및 갈등 | C25: 노사공동교육·워크숍 — 시행여부 | D25: 시행 / 미시행
A26: Q17_3A | B26: 노사협력 및 갈등 | C26: 노사공동교육·워크숍 — 활성화 정도(시행한 경우만) | D26: 1~5 (시행한 경우만)
A27: Q17_4 | B27: 노사협력 및 갈등 | C27: 직원단합대회(체육대회, 등반대회, 야유회 등) — 시행여부 | D27: 시행 / 미시행
A28: Q17_4A | B28: 노사협력 및 갈등 | C28: 직원단합대회(체육대회, 등반대회, 야유회 등) — 활성화 정도(시행한 경우만) | D28: 1~5 (시행한 경우만)
A29: Q17_5 | B29: 노사협력 및 갈등 | C29: 노사공동 사회봉사(일사일촌 등) — 시행여부 | D29: 시행 / 미시행
A30: Q17_5A | B30: 노사협력 및 갈등 | C30: 노사공동 사회봉사(일사일촌 등) — 활성화 정도(시행한 경우만) | D30: 1~5 (시행한 경우만)
A31: 문18. 노사 간 갈등(최근 3년) — 발생 여부
A32: Q18_1 | B32: 노사협력 및 갈등 | C32: 파업(부분파업 포함) 발생 | D32: 발생 / 미발생
A33: Q18_2 | B33: 노사협력 및 갈등 | C33: 노사문제로 인한 경제적 손실 발생 | D33: 발생 / 미발생
A34: Q18_3 | B34: 노사협력 및 갈등 | C34: 노사문제로 인한 고소·고발 발생 | D34: 발생 / 미발생
A35: Q18_4 | B35: 노사협력 및 갈등 | C35: 노사문제로 인한 해고자 발생 | D35: 발생 / 미발생
A36: 문19. 근로자 고충처리 — 우리 회사는 …
A37: Q19_1 | B37: 고충처리 | C37: 근로자의 고충을 전달할 공식적인 통로를 충분히 제공하고 있다 | D37: 1~5 (1 전혀 그렇지 않다 · 3 보통 · 5 매우 그렇다)
A38: Q19_2 | B38: 고충처리 | C38: 고충 제기 후 처리과정에서 노사 간 의사소통이 수시로 이루어진다 | D38: 1~5 (1 전혀 그렇지 않다 · 3 보통 · 5 매우 그렇다)
A39: Q19_3 | B39: 고충처리 | C39: 근로자의 고충을 효과적으로 처리한다 | D39: 1~5 (1 전혀 그렇지 않다 · 3 보통 · 5 매우 그렇다)
A40: Q19_4 | B40: 고충처리 | C40: 고충처리에 대해 근로자들은 만족하고 있다 | D40: 1~5 (1 전혀 그렇지 않다 · 3 보통 · 5 매우 그렇다)
A41: 문20. (참고·점수 미반영) 지난해 제기된 고충의 해결 정도
A42: Q20 | B42: 참고 | C42: 1=30%미만 2=30~50% 3=50~70% 4=70~90% 5=90%이상 | D42: 1~5
A43: 문21. 근로자(대표)와의 의사소통 — 우리 회사는 …
...

Sheet 결과
B1: 노사관계 진단 결과
B2: 노란 칸에서 조건을 고르면 자동 계산됩니다. 점수는 재단 일터혁신지수 노사관계 영역과 같은 구조(100점)입니다.
B4: 응답자 유형 | C4: 사업주·담당자 | D4: 벤치마크는 사업주·담당자 응답 기준
B5: 비교 연도 | C5: 2025 | D5: 2025=최신(2025식 계산), 2024(보정)=갈등 이상치 보정
B6: 비교 집단 | C6: 자동 | D6: 자동=설문 기본정보의 컨설팅 수혜 여부를 따름
B7: 적용 계산식 | C7: =IF(C5&""="2025","2025식","2023·24식") | D7: ="기관: "&IF(설문!$C$4="","(미입력)",설문!$C$4)&" · "&설문!$C$5&" · "&설문!$C$6&" · 노조 "&설문!$C$7&" · 노사협의회 "&설문!$C$8
B8: 적용 비교집단 | C8: =IF(C6="자동",IF(설문!$C$9="받음(수혜)","수혜","일반"),C6)
B9: 문항 비교 기준연도 | C9: =IF(C5&""="2024(보정)","2024",C5&"")
B11: ■ 종합
B12: 응답자 수(유효) | C12: =COUNTIFS(점수_응답자!$E$4:$BB$4,$C$4,점수_응답자!$E$5:$BB$5,1)
B13: 종합점수(100점) | C13: =IFERROR(SUM(E23:E29)/SUMPRODUCT(D23:D29,--(E23:E29<>""))*100,"") | D13: =IF(C13="","",REPT("■",ROUND(C13/5,0))&REPT("□",20-ROUND(C13/5,0)))
B14: 벤치마크(배점 반영) | C14: =IFERROR(SUMPRODUCT(D23:D29,G23:G29,--(E23:E29<>""))/SUMPRODUCT(D23:D29,--(E23:E29<>""))*100,"") | D14: =IF(C14="","",REPT("■",ROUND(C14/5,0))&REPT("□",20-ROUND(C14/5,0)))
B15: 공식 공표 총점(참고) | C15: =IFERROR(INDEX(벤치마크!$E$65:$E$160,MATCH($C$5&"|"&$C$8&"|"&"전체",벤치마크!$A$65:$A$160,0)),"")
B16: 벤치마크 대비 차이 | C16: =IF(OR(C13="",C14=""),"",C13-C14)
B17: 진단 등급 | C17: =IF(C16="","",IF(C16>=10,"S 매우 우수",IF(C16>=3,"A 우수",IF(C16>-3,"B 평균 수준",IF(C16>-10,"C 미흡","D 매우 미흡")))))
B18: 한 줄 해석 | C18: =IF(C16="","응답을 입력하면 해석이 표시됩니다.","같은 해 "&$C$8&"사업장 평균보다 "&TEXT(ABS(C16),"0.0")&"점 "&IF(C16>=0,"높습니다.","낮습니다.")&IF(C43="",""," 가장 큰 개선 여지는 ‘"&C43&"’입니다."))
B20: ■ 소분류(파트)별 점수 — 막대: ■=우리 달성률, 숫자=벤치마크 달성률
B22: 파트 | C22: 중분류 | D22: 배점 | E22: 우리 점수 | F22: 우리 달성률 | G22: 벤치 달성률 | H22: 벤치 점수 | I22: 차이(점) | J22: 막대(우리 달성률) | K22: 판정
B23: P1 노사관계 전반 인식 | C23: 노사관계분위기 | D23: =가중치!$F$45 | E23: =IF($C$7="2025식",IFERROR(AVERAGEIFS(점수_응답자!$E$128:$BB$128,점수_응답자!$E$4:$BB$4,$C$4,점수_응답자!$E$5:$BB$5,1),""),IFERROR(AVERAGEIFS(점수_응답자!$E$138:$BB$138,점수_응답자!$E$4:$BB$4,$C$4,점수_응답자!$E$5:$BB$5,1),"")) | F23: =IF(E23="","",E23/D23) | G23: =IFERROR(INDEX(벤치마크!$E$6:$E$61,MATCH($C$5&"|"&$C$8&"|"&"P1",벤치마크!$A$6:$A$61,0)),"") | H23: =IF(G23="","",G23*D23) | I23: =IF(OR(E23="",H23=""),"",E23-H23) | J23: =IF(F23="","",REPT("■",ROUND(F23*10,0))&REPT("□",10-ROUND(F23*10,0))) | K23: =IF(I23="","",IF(I23>=0.5,"강점",IF(I23<=-0.5,"약점","보통"))) | L23: =IF(E23="",-1,D23-E23+ROW()/1000000)
B24: P2 노조·근로자대표의 혁신 태도 | C24: 노사관계분위기 | D24: =가중치!$F$46 | E24: =IF($C$7="2025식",IFERROR(AVERAGEIFS(점수_응답자!$E$129:$BB$129,점수_응답자!$E$4:$BB$4,$C$4,점수_응답자!$E$5:$BB$5,1),""),IFERROR(AVERAGEIFS(점수_응답자!$E$139:$BB$139,점수_응답자!$E$4:$BB$4,$C$4,점수_응답자!$E$5:$BB$5,1),"")) | F24: =IF(E24="","",E24/D24) | G24: =IFERROR(INDEX(벤치마크!$E$6:$E$61,MATCH($C$5&"|"&$C$8&"|"&"P2",벤치마크!$A$6:$A$61,0)),"") | H24: =IF(G24="","",G24*D24) | I24: =IF(OR(E24="",H24=""),"",E24-H24) | J24: =IF(F24="","",REPT("■",ROUND(F24*10,0))&REPT("□",10-ROUND(F24*10,0))) | K24: =IF(I24="","",IF(I24>=0.5,"강점",IF(I24<=-0.5,"약점","보통"))) | L24: =IF(E24="",-1,D24-E24+ROW()/1000000)
B25: P3 노사협력 프로그램 | C25: 노사협력 및 갈등 | D25: =가중치!$F$47 | E25: =IF($C$7="2025식",IFERROR(AVERAGEIFS(점수_응답자!$E$130:$BB$130,점수_응답자!$E$4:$BB$4,$C$4,점수_응답자!$E$5:$BB$5,1),""),IFERROR(AVERAGEIFS(점수_응답자!$E$140:$BB$140,점수_응답자!$E$4:$BB$4,$C$4,점수_응답자!$E$5:$BB$5,1),"")) | F25: =IF(E25="","",E25/D25) | G25: =IFERROR(INDEX(벤치마크!$E$6:$E$61,MATCH($C$5&"|"&$C$8&"|"&"P3",벤치마크!$A$6:$A$61,0)),"") | H25: =IF(G25="","",G25*D25) | I25: =IF(OR(E25="",H25=""),"",E25-H25) | J25: =IF(F25="","",REPT("■",ROUND(F25*10,0))&REPT("□",10-ROUND(F25*10,0))) | K25: =IF(I25="","",IF(I25>=0.5,"강점",IF(I25<=-0.5,"약점","보통"))) | L25: =IF(E25="",-1,D25-E25+ROW()/1000000)
B26: P4 노사갈등(미발생) | C26: 노사협력 및 갈등 | D26: =가중치!$F$48 | E26: =IF($C$7="2025식",IFERROR(AVERAGEIFS(점수_응답자!$E$131:$BB$131,점수_응답자!$E$4:$BB$4,$C$4,점수_응답자!$E$5:$BB$5,1),""),IFERROR(AVERAGEIFS(점수_응답자!$E$141:$BB$141,점수_응답자!$E$4:$BB$4,$C$4,점수_응답자!$E$5:$BB$5,1),"")) | F26: =IF(E26="","",E26/D26) | G26: =IFERROR(INDEX(벤치마크!$E$6:$E$61,MATCH($C$5&"|"&$C$8&"|"&"P4",벤치마크!$A$6:$A$61,0)),"") | H26: =IF(G26="","",G26*D26) | I26: =IF(OR(E26="",H26=""),"",E26-H26) | J26: =IF(F26="","",REPT("■",ROUND(F26*10,0))&REPT("□",10-ROUND(F26*10,0))) | K26: =IF(I26="","",IF(I26>=0.5,"강점",IF(I26<=-0.5,"약점","보통"))) | L26: =IF(E26="",-1,D26-E26+ROW()/1000000)
B27: P5 정보공유·의사소통 | C27: 정보공유와 의사소통 | D27: =가중치!$F$49 | E27: =IF($C$7="2025식",IFERROR(AVERAGEIFS(점수_응답자!$E$132:$BB$132,점수_응답자!$E$4:$BB$4,$C$4,점수_응답자!$E$5:$BB$5,1),""),IFERROR(AVERAGEIFS(점수_응답자!$E$142:$BB$142,점수_응답자!$E$4:$BB$4,$C$4,점수_응답자!$E$5:$BB$5,1),"")) | F27: =IF(E27="","",E27/D27) | G27: =IFERROR(INDEX(벤치마크!$E$6:$E$61,MATCH($C$5&"|"&$C$8&"|"&"P5",벤치마크!$A$6:$A$61,0)),"") | H27: =IF(G27="","",G27*D27) | I27: =IF(OR(E27="",H27=""),"",E27-H27) | J27: =IF(F27="","",REPT("■",ROUND(F27*10,0))&REPT("□",10-ROUND(F27*10,0))) | K27: =IF(I27="","",IF(I27>=0.5,"강점",IF(I27<=-0.5,"약점","보통"))) | L27: =IF(E27="",-1,D27-E27+ROW()/1000000)
B28: P6 고충처리 | C28: 고충처리 | D28: =가중치!$F$50 | E28: =IF($C$7="2025식",IFERROR(AVERAGEIFS(점수_응답자!$E$133:$BB$133,점수_응답자!$E$4:$BB$4,$C$4,점수_응답자!$E$5:$BB$5,1),""),IFERROR(AVERAGEIFS(점수_응답자!$E$143:$BB$143,점수_응답자!$E$4:$BB$4,$C$4,점수_응답자!$E$5:$BB$5,1),"")) | F28: =IF(E28="","",E28/D28) | G28: =IFERROR(INDEX(벤치마크!$E$6:$E$61,MATCH($C$5&"|"&$C$8&"|"&"P6",벤치마크!$A$6:$A$61,0)),"") | H28: =IF(G28="","",G28*D28) | I28: =IF(OR(E28="",H28=""),"",E28-H28) | J28: =IF(F28="","",REPT("■",ROUND(F28*10,0))&REPT("□",10-ROUND(F28*10,0))) | K28: =IF(I28="","",IF(I28>=0.5,"강점",IF(I28<=-0.5,"약점","보통"))) | L28: =IF(E28="",-1,D28-E28+ROW()/1000000)
B29: P7 노사협의회 활용성 | C29: 노사협의회 | D29: =가중치!$F$51 | E29: =IF($C$7="2025식",IFERROR(AVERAGEIFS(점수_응답자!$E$134:$BB$134,점수_응답자!$E$4:$BB$4,$C$4,점수_응답자!$E$5:$BB$5,1),""),IFERROR(AVERAGEIFS(점수_응답자!$E$144:$BB$144,점수_응답자!$E$4:$BB$4,$C$4,점수_응답자!$E$5:$BB$5,1),"")) | F29: =IF(E29="","",E29/D29) | G29: =IFERROR(INDEX(벤치마크!$E$6:$E$61,MATCH($C$5&"|"&$C$8&"|"&"P7",벤치마크!$A$6:$A$61,0)),"") | H29: =IF(G29="","",G29*D29) | I29: =IF(OR(E29="",H29=""),"",E29-H29) | J29: =IF(F29="","",REPT("■",ROUND(F29*10,0))&REPT("□",10-ROUND(F29*10,0))) | K29: =IF(I29="","",IF(I29>=0.5,"강점",IF(I29<=-0.5,"약점","보통"))) | L29: =IF(E29="",-1,D29-E29+ROW()/1000000)
B30: 합계 | D30: =SUM(D23:D29) | E30: =IF(COUNT(E23:E29)=0,"",SUM(E23:E29)) | H30: =SUM(H23:H29)
B31: ※ 노사협의회 미설치·50인 미만·무노조이면 노사협의회 파트를 빼고 100점으로 환산합니다(그 밖의 미설치는 0점).
B33: ■ 중분류(공식 5개 하위부문)
B34: 중분류 | C34: 배점 | D34: 우리 점수 | E34: 달성률 | F34: 벤치 점수 | G34: 차이(점)
B35: 노사관계분위기 | C35: =SUMIF($C$23:$C$29,B35,$D$23:$D$29) | D35: =IF(COUNTIFS($C$23:$C$29,B35,$E$23:$E$29,">=0")=0,"",SUMIF($C$23:$C$29,B35,$E$23:$E$29)) | E35: =IF(D35="","",D35/C35) | F35: =SUMIF($C$23:$C$29,B35,$H$23:$H$29) | G35: =IF(D35="","",D35-F35)
B36: 노사협력 및 갈등 | C36: =SUMIF($C$23:$C$29,B36,$D$23:$D$29) | D36: =IF(COUNTIFS($C$23:$C$29,B36,$E$23:$E$29,">=0")=0,"",SUMIF($C$23:$C$29,B36,$E$23:$E$29)) | E36: =IF(D36="","",D36/C36) | F36: =SUMIF($C$23:$C$29,B36,$H$23:$H$29) | G36: =IF(D36="","",D36-F36)
B37: 정보공유와 의사소통 | C37: =SUMIF($C$23:$C$29,B37,$D$23:$D$29) | D37: =IF(COUNTIFS($C$23:$C$29,B37,$E$23:$E$29,">=0")=0,"",SUMIF($C$23:$C$29,B37,$E$23:$E$29)) | E37: =IF(D37="","",D37/C37) | F37: =SUMIF($C$23:$C$29,B37,$H$23:$H$29) | G37: =IF(D37="","",D37-F37)
B38: 고충처리 | C38: =SUMIF($C$23:$C$29,B38,$D$23:$D$29) | D38: =IF(COUNTIFS($C$23:$C$29,B38,$E$23:$E$29,">=0")=0,"",SUMIF($C$23:$C$29,B38,$E$23:$E$29)) | E38: =IF(D38="","",D38/C38) | F38: =SUMIF($C$23:$C$29,B38,$H$23:$H$29) | G38: =IF(D38="","",D38-F38)
B39: 노사협의회 | C39: =SUMIF($C$23:$C$29,B39,$D$23:$D$29) | D39: =IF(COUNTIFS($C$23:$C$29,B39,$E$23:$E$29,">=0")=0,"",SUMIF($C$23:$C$29,B39,$E$23:$E$29)) | E39: =IF(D39="","",D39/C39) | F39: =SUMIF($C$23:$C$29,B39,$H$23:$H$29) | G39: =IF(D39="","",D39-F39)
B41: ■ 우선 개선과제 TOP 3 — ‘잃은 점수’(배점−우리 점수)가 큰 순
B42: 순위 | C42: 파트 | D42: 잃은 점수 | E42: 벤치 대비 | F42: 처방
B43: 1 | C43: =IF(LARGE($L$23:$L$29,1)<0,"",INDEX($B$23:$B$29,MATCH(LARGE($L$23:$L$29,1),$L$23:$L$29,0))) | D43: =IF(C43="","",INDEX($D$23:$D$29,MATCH(LARGE($L$23:$L$29,1),$L$23:$L$29,0))-INDEX($E$23:$E$29,MATCH(LARGE($L$23:$L$29,1),$L$23:$L$29,0))) | E43: =IF(C43="","",INDEX($I$23:$I$29,MATCH(LARGE($L$23:$L$29,1),$L$23:$L$29,0))) | F43: =IF(C43="","",INDEX(벤치마크!$B$320:$B$326,MATCH(LEFT(C43,2),벤치마크!$A$320:$A$326,0)))
B44: 2 | C44: =IF(LARGE($L$23:$L$29,2)<0,"",INDEX($B$23:$B$29,MATCH(LARGE($L$23:$L$29,2),$L$23:$L$29,0))) | D44: =IF(C44="","",INDEX($D$23:$D$29,MATCH(LARGE($L$23:$L$29,2),$L$23:$L$29,0))-INDEX($E$23:$E$29,MATCH(LARGE($L$23:$L$29,2),$L$23:$L$29,0))) | E44: =IF(C44="","",INDEX($I$23:$I$29,MATCH(LARGE($L$23:$L$29,2),$L$23:$L$29,0))) | F44: =IF(C44="","",INDEX(벤치마크!$B$320:$B$326,MATCH(LEFT(C44,2),벤치마크!$A$320:$A$326,0)))
B45: 3 | C45: =IF(LARGE($L$23:$L$29,3)<0,"",INDEX($B$23:$B$29,MATCH(LARGE($L$23:$L$29,3),$L$23:$L$29,0))) | D45: =IF(C45="","",INDEX($D$23:$D$29,MATCH(LARGE($L$23:$L$29,3),$L$23:$L$29,0))-INDEX($E$23:$E$29,MATCH(LARGE($L$23:$L$29,3),$L$23:$L$29,0))) | E45: =IF(C45="","",INDEX($I$23:$I$29,MATCH(LARGE($L$23:$L$29,3),$L$23:$L$29,0))) | F45: =IF(C45="","",INDEX(벤치마크!$B$320:$B$326,MATCH(LEFT(C45,2),벤치마크!$A$320:$A$326,0)))
B47: ■ 같은 조건 사업장과 비교(공식 공표 총점)
...

Sheet 가중치
A1: 문항별 가중치(배점) — 역산 결과
A2: E열=2023~2025 공식 지수에서 역산한 배점(블록 배점 ÷ 문항 수, 블록 안 동일가중 검증). F열(노란 칸)을 바꾸면 결과에 바로 반영. 되돌리려면 E열 값을 F열에 복사.
A4: 문항ID | B4: 중분류 | C4: 소분류(파트) | D4: 문항 | E4: 공식 역산 배점 | F4: 적용 배점 | G4: 근거·신뢰도
A5: Q16_1 | B5: 노사관계분위기 | C5: 노사관계 전반 인식 | D5: 노사의 이해관계가 크게 다르지 않아 협조가 잘 이루어진다 | E5: 2.5 | F5: 2.5 | G5: A 검증: 2023·2024·2025 표준화값을 문항평균으로 재현(14/14 블록)
A6: Q16_2 | B6: 노사관계분위기 | C6: 노사관계 전반 인식 | D6: 노사가 서로 상대방의 일에 대해 반대하지 않는다 | E6: 2.5 | F6: 2.5 | G6: A 검증: 2023·2024·2025 표준화값을 문항평균으로 재현(14/14 블록)
A7: Q16_3 | B7: 노사관계분위기 | C7: 노사관계 전반 인식 | D7: 노사 모두가 회사를 더욱 일하기 좋은 곳으로 만들려고 노력한다 | E7: 2.5 | F7: 2.5 | G7: A 검증: 2023·2024·2025 표준화값을 문항평균으로 재현(14/14 블록)
A8: Q16_4 | B8: 노사관계분위기 | C8: 노사관계 전반 인식 | D8: 그간 노사관계가 협력적이었다 | E8: 2.5 | F8: 2.5 | G8: A 검증: 2023·2024·2025 표준화값을 문항평균으로 재현(14/14 블록)
A9: Q24_1 | B9: 노사관계분위기 | C9: 노조·근로자대표의 혁신 태도 | D9: 일터혁신과 관련된 인적자원개발(교육훈련 등) 활동을 지지한다 | E9: 2 | F9: 2 | G9: A 검증: 2023·2024·2025 표준화값을 문항평균으로 재현(14/14 블록)
A10: Q24_2 | B10: 노사관계분위기 | C10: 노조·근로자대표의 혁신 태도 | D10: 일터혁신과 관련하여 고용안정을 위해 노력한다 | E10: 2 | F10: 2 | G10: A 검증: 2023·2024·2025 표준화값을 문항평균으로 재현(14/14 블록)
A11: Q24_3 | B11: 노사관계분위기 | C11: 노조·근로자대표의 혁신 태도 | D11: 일터혁신과 관련된 작업장에서의 직원 참여활동을 지지한다 | E11: 2 | F11: 2 | G11: A 검증: 2023·2024·2025 표준화값을 문항평균으로 재현(14/14 블록)
A12: Q24_4 | B12: 노사관계분위기 | C12: 노조·근로자대표의 혁신 태도 | D12: 일터혁신과 관련된 인적자원관리(보상, 평가 등) 활동을 지지한다 | E12: 2 | F12: 2 | G12: A 검증: 2023·2024·2025 표준화값을 문항평균으로 재현(14/14 블록)
A13: Q24_5 | B13: 노사관계분위기 | C13: 노조·근로자대표의 혁신 태도 | D13: 일터혁신 전반에 대해 지지한다 | E13: 2 | F13: 2 | G13: A 검증: 2023·2024·2025 표준화값을 문항평균으로 재현(14/14 블록)
A14: Q17_1 | B14: 노사협력 및 갈등 | C14: 노사협력 프로그램 | D14: 노사협력선언·노사공동결의대회 | E14: 2.6 | F14: 2.6 | G14: B/C: 2023식 재현, 2024·2025 공표값 미재현(공개 집계 한계)
A15: Q17_2 | B15: 노사협력 및 갈등 | C15: 노사협력 프로그램 | D15: 노사공동기구·위원회를 통한 문제해결 | E15: 2.6 | F15: 2.6 | G15: B/C: 2023식 재현, 2024·2025 공표값 미재현(공개 집계 한계)
A16: Q17_3 | B16: 노사협력 및 갈등 | C16: 노사협력 프로그램 | D16: 노사공동교육·워크숍 | E16: 2.6 | F16: 2.6 | G16: B/C: 2023식 재현, 2024·2025 공표값 미재현(공개 집계 한계)
... A40: Q23_5 | B40: 노사협의회 | C40: 노사협의회 활용성 | D40: 작업장 내 생산성 향상을 위한 논의 창구로 활용된다 | E40: 3 | F40: 3 | G40: A 검증: 2023·2024·2025 표준화값을 문항평균으로 재현(14/14 블록)
A42: 합계 | E42: =SUM(E5:E40) | F42: =SUM(F5:F40)
A44: 파트 | B44: 중분류 | C44: 소분류 | D44: 문항 수 | E44: 공식 배점 | F44: 적용 배점
A45: P1 | B45: 노사관계분위기 | C45: 노사관계 전반 인식 | D45: 4 | E45: =SUMIF($C$5:$C$40,C45,$E$5:$E$40) | F45: =SUMIF($C$5:$C$40,C45,$F$5:$F$40)
A46: P2 | B46: 노사관계분위기 | C46: 노조·근로자대표의 혁신 태도 | D46: 5 | E46: =SUMIF($C$5:$C$40,C46,$E$5:$E$40) | F46: =SUMIF($C$5:$C$40,C46,$F$5:$F$40)
A47: P3 | B47: 노사협력 및 갈등 | C47: 노사협력 프로그램 | D47: 5 | E47: =SUMIF($C$5:$C$40,C47,$E$5:$E$40) | F47: =SUMIF($C$5:$C$40,C47,$F$5:$F$40)
A48: P4 | B48: 노사협력 및 갈등 | C48: 노사갈등(미발생) | D48: 4 | E48: =SUMIF($C$5:$C$40,C48,$E$5:$E$40) | F48: =SUMIF($C$5:$C$40,C48,$F$5:$F$40)
A49: P5 | B49: 정보공유와 의사소통 | C49: 정보공유·의사소통 | D49: 9 | E49: =SUMIF($C$5:$C$40,C49,$E$5:$E$40) | F49: =SUMIF($C$5:$C$40,C49,$F$5:$F$40)
A50: P6 | B50: 고충처리 | C50: 고충처리 | D50: 4 | E50: =SUMIF($C$5:$C$40,C50,$E$5:$E$40) | F50: =SUMIF($C$5:$C$40,C50,$F$5:$F$40)
A51: P7 | B51: 노사협의회 | C51: 노사협의회 활용성 | D51: 5 | E51: =SUMIF($C$5:$C$40,C51,$E$5:$E$40) | F51: =SUMIF($C$5:$C$40,C51,$F$5:$F$40)

Sheet 벤치마크
A1: 공식 벤치마크 — 노사발전재단 일터혁신 실태조사(사업주·인사노무 담당자 응답)
A2: 2023 표 Ⅴ-8·Ⅴ-10 / 2024 표 Ⅵ-8·Ⅵ-10·Ⅳ-2.1~2.11 / 2025 표 Ⅵ-9·Ⅵ-11·Ⅲ-2.1~2.4. 2024(보정)=갈등 블록만 공표 발생률로 재계산.
A4: ① 파트별 표준화값(0~1)
A5: 키 | B5: 연도 | C5: 집단 | D5: 파트 | E5: 표준화값 | F5: ×공식배점 | G5: 비고
A6: 2023|수혜|P1 | B6: 2023 | C6: 수혜 | D6: P1 | E6: 0.7356 | F6: =E6*10
A7: 2023|수혜|P2 | B7: 2023 | C7: 수혜 | D7: P2 | E7: 0.7334 | F7: =E7*10
A8: 2023|수혜|P3 | B8: 2023 | C8: 수혜 | D8: P3 | E8: 0.3818 | F8: =E8*13
A9: 2023|수혜|P4 | B9: 2023 | C9: 수혜 | D9: P4 | E9: 0.9786 | F9: =E9*12
A10: 2023|수혜|P5 | B10: 2023 | C10: 수혜 | D10: P5 | E10: 0.7334 | F10: =E10*25
A11: 2023|수혜|P6 | B11: 2023 | C11: 수혜 | D11: P6 | E11: 0.7123 | F11: =E11*15
A12: 2023|수혜|P7 | B12: 2023 | C12: 수혜 | D12: P7 | E12: 0.6915 | F12: =E12*15
A13: 2023|일반|P1 | B13: 2023 | C13: 일반 | D13: P1 | E13: 0.701 | F13: =E13*10
A14: 2023|일반|P2 | B14: 2023 | C14: 일반 | D14: P2 | E14: 0.6705 | F14: =E14*10
A15: 2023|일반|P3 | B15: 2023 | C15: 일반 | D15: P3 | E15: 0.3515 | F15: =E15*13
A16: 2023|일반|P4 | B16: 2023 | C16: 일반 | D16: P4 | E16: 0.977 | F16: =E16*12
A17: 2023|일반|P5 | B17: 2023 | C17: 일반 | D17: P5 | E17: 0.6695 | F17: =E17*25
A18: 2023|일반|P6 | B18: 2023 | C18: 일반 | D18: P6 | E18: 0.6905 | F18: =E18*15
A19: 2023|일반|P7 | B19: 2023 | C19: 일반 | D19: P7 | E19: 0.6606 | F19: =E19*15
A20: 2024|수혜|P1 | B20: 2024 | C20: 수혜 | D20: P1 | E20: 0.7455 | F20: =E20*10
A21: 2024|수혜|P2 | B21: 2024 | C21: 수혜 | D21: P2 | E21: 0.7434 | F21: =E21*10
A22: 2024|수혜|P3 | B22: 2024 | C22: 수혜 | D22: P3 | E22: 0.3813 | F22: =E22*13
A23: 2024|수혜|P4 | B23: 2024 | C23: 수혜 | D23: P4 | E23: 0.6619 | F23: =E23*12 | G23: 갈등 0.6619는 공표 발생률(평균 2.1%)과 맞지 않는 이상치
A24: 2024|수혜|P5 | B24: 2024 | C24: 수혜 | D24: P5 | E24: 0.693 | F24: =E24*25
A25: 2024|수혜|P6 | B25: 2024 | C25: 수혜 | D25: P6 | E25: 0.7072 | F25: =E25*15
A26: 2024|수혜|P7 | B26: 2024 | C26: 수혜 | D26: P7 | E26: 0.6903 | F26: =E26*15
A27: 2024|일반|P1 | B27: 2024 | C27: 일반 | D27: P1 | E27: 0.721 | F27: =E27*10
A28: 2024|일반|P2 | B28: 2024 | C28: 일반 | D28: P2 | E28: 0.6862 | F28: =E28*10
A29: 2024|일반|P3 | B29: 2024 | C29: 일반 | D29: P3 | E29: 0.3011 | F29: =E29*13
A30: 2024|일반|P4 | B30: 2024 | C30: 일반 | D30: P4 | E30: 0.5087 | F30: =E30*12 | G30: 갈등 0.5087은 공표 발생률(평균 2.6%)과 맞지 않는 이상치
A31: 2024|일반|P5 | B31: 2024 | C31: 일반 | D31: P5 | E31: 0.6721 | F31: =E31*25
A32: 2024|일반|P6 | B32: 2024 | C32: 일반 | D32: P6 | E32: 0.6973 | F32: =E32*15
A33: 2024|일반|P7 | B33: 2024 | C33: 일반 | D33: P7 | E33: 0.667 | F33: =E33*15
A34: 2025|수혜|P1 | B34: 2025 | C34: 수혜 | D34: P1 | E34: 0.6779 | F34: =E34*10 | G34: 표 Ⅵ-9 수혜 세부값 5개가 2024값과 동일하게 기재(표준화값은 신규)
A35: 2025|수혜|P2 | B35: 2025 | C35: 수혜 | D35: P2 | E35: 0.6887 | F35: =E35*10 | G35: 표 Ⅵ-9 수혜 세부값 5개가 2024값과 동일하게 기재(표준화값은 신규)
A36: 2025|수혜|P3 | B36: 2025 | C36: 수혜 | D36: P3 | E36: 0.3836 | F36: =E36*13 | G36: 표 Ⅵ-9 수혜 세부값 5개가 2024값과 동일하게 기재(표준화값은 신규)
A37: 2025|수혜|P4 | B37: 2025 | C37: 수혜 | D37: P4 | E37: 0.979 | F37: =E37*12 | G37: 표 Ⅵ-9 수혜 세부값 5개가 2024값과 동일하게 기재(표준화값은 신규)
A38: 2025|수혜|P5 | B38: 2025 | C38: 수혜 | D38: P5 | E38: 0.6302 | F38: =E38*25 | G38: 표 Ⅵ-9 수혜 세부값 5개가 2024값과 동일하게 기재(표준화값은 신규)
A39: 2025|수혜|P6 | B39: 2025 | C39: 수혜 | D39: P6 | E39: 0.6788 | F39: =E39*15 | G39: 표 Ⅵ-9 수혜 세부값 5개가 2024값과 동일하게 기재(표준화값은 신규)
A40: 2025|수혜|P7 | B40: 2025 | C40: 수혜 | D40: P7 | E40: 0.628 | F40: =E40*15 | G40: 표 Ⅵ-9 수혜 세부값 5개가 2024값과 동일하게 기재(표준화값은 신규)
A41: 2025|일반|P1 | B41: 2025 | C41: 일반 | D41: P1 | E41: 0.634 | F41: =E41*10
...

Sheet 역산검증
A1: 역산검증 — 공표 문항평균으로 공식 표준화값을 재현(수식이 실시간 계산)
A2: 판정 허용오차: 문항평균은 소수 둘째 자리 반올림(±0.005)이므로 x/5는 ±0.00105, (x−1)/4는 ±0.0013 이내면 ‘일치’.
A4: 연도 | B4: 집단 | C4: 블록 | D4: 평균1 | E4: 평균2 | F4: 평균3 | G4: 평균4 | H4: 평균5 | I4: 평균6 | J4: 평균7 | K4: 평균8 | L4: 평균9 | M4: 블록평균 | N4: x/5 | O4: (x−1)/4 | P4: 공식값 | Q4: x/5 판정 | R4: (x−1)/4 판정
A5: 2023 | B5: 수혜 | C5: Q16 | D5: 3.54 | E5: 3.56 | F5: 3.84 | G5: 3.77 | M5: =AVERAGE(D5:L5) | N5: =M5/5 | O5: =(M5-1)/4 | P5: 0.7356 | Q5: =IF(ABS(N5-P5)<=0.00105,"일치","불일치") | R5: =IF(ABS(O5-P5)<=0.0013,"일치","불일치")
A6: 2023 | B6: 일반 | C6: Q16 | D6: 3.39 | E6: 3.4 | F6: 3.65 | G6: 3.58 | M6: =AVERAGE(D6:L6) | N6: =M6/5 | O6: =(M6-1)/4 | P6: 0.701 | Q6: =IF(ABS(N6-P6)<=0.00105,"일치","불일치") | R6: =IF(ABS(O6-P6)<=0.0013,"일치","불일치")
A7: 2024 | B7: 수혜 | C7: Q16 | D7: 3.57 | E7: 3.58 | F7: 3.93 | G7: 3.83 | M7: =AVERAGE(D7:L7) | N7: =M7/5 | O7: =(M7-1)/4 | P7: 0.7455 | Q7: =IF(ABS(N7-P7)<=0.00105,"일치","불일치") | R7: =IF(ABS(O7-P7)<=0.0013,"일치","불일치")
A8: 2024 | B8: 일반 | C8: Q16 | D8: 3.49 | E8: 3.48 | F8: 3.76 | G8: 3.69 | M8: =AVERAGE(D8:L8) | N8: =M8/5 | O8: =(M8-1)/4 | P8: 0.721 | Q8: =IF(ABS(N8-P8)<=0.00105,"일치","불일치") | R8: =IF(ABS(O8-P8)<=0.0013,"일치","불일치")
A9: 2024 | B9: 수혜 | C9: Q19 | D9: 3.62 | E9: 3.6 | F9: 3.56 | G9: 3.36 | M9: =AVERAGE(D9:L9) | N9: =M9/5 | O9: =(M9-1)/4 | P9: 0.7072 | Q9: =IF(ABS(N9-P9)<=0.00105,"일치","불일치") | R9: =IF(ABS(O9-P9)<=0.0013,"일치","불일치")
A10: 2024 | B10: 일반 | C10: Q19 | D10: 3.55 | E10: 3.54 | F10: 3.48 | G10: 3.38 | M10: =AVERAGE(D10:L10) | N10: =M10/5 | O10: =(M10-1)/4 | P10: 0.6973 | Q10: =IF(ABS(N10-P10)<=0.00105,"일치","불일치") | R10: =IF(ABS(O10-P10)<=0.0013,"일치","불일치")
A11: 2024 | B11: 수혜 | C11: Q21+22 | D11: 3.64 | E11: 3.41 | F11: 3.46 | G11: 3.57 | H11: 3.37 | I11: 3.55 | J11: 3.31 | K11: 3.43 | L11: 3.44 | M11: =AVERAGE(D11:L11) | N11: =M11/5 | O11: =(M11-1)/4 | P11: 0.693 | Q11: =IF(ABS(N11-P11)<=0.00105,"일치","불일치") | R11: =IF(ABS(O11-P11)<=0.0013,"일치","불일치")
A12: 2024 | B12: 일반 | C12: Q21+22 | D12: 3.48 | E12: 3.27 | F12: 3.34 | G12: 3.45 | H12: 3.24 | I12: 3.48 | J12: 3.26 | K12: 3.31 | L12: 3.41 | M12: =AVERAGE(D12:L12) | N12: =M12/5 | O12: =(M12-1)/4 | P12: 0.6721 | Q12: =IF(ABS(N12-P12)<=0.00105,"일치","불일치") | R12: =IF(ABS(O12-P12)<=0.0013,"일치","불일치")
A13: 2024 | B13: 수혜 | C13: Q23 | D13: 3.27 | E13: 3.4 | F13: 3.57 | G13: 3.65 | H13: 3.35 | M13: =AVERAGE(D13:L13) | N13: =M13/5 | O13: =(M13-1)/4 | P13: 0.6903 | Q13: =IF(ABS(N13-P13)<=0.00105,"일치","불일치") | R13: =IF(ABS(O13-P13)<=0.0013,"일치","불일치")
A14: 2024 | B14: 일반 | C14: Q23 | D14: 3.18 | E14: 3.24 | F14: 3.46 | G14: 3.49 | H14: 3.3 | M14: =AVERAGE(D14:L14) | N14: =M14/5 | O14: =(M14-1)/4 | P14: 0.667 | Q14: =IF(ABS(N14-P14)<=0.00105,"일치","불일치") | R14: =IF(ABS(O14-P14)<=0.0013,"일치","불일치")
A15: 2024 | B15: 수혜 | C15: Q24 | D15: 3.7 | E15: 3.79 | F15: 3.72 | G15: 3.65 | H15: 3.73 | M15: =AVERAGE(D15:L15) | N15: =M15/5 | O15: =(M15-1)/4 | P15: 0.7434 | Q15: =IF(ABS(N15-P15)<=0.00105,"일치","불일치") | R15: =IF(ABS(O15-P15)<=0.0013,"일치","불일치")
A16: 2024 | B16: 일반 | C16: Q24 | D16: 3.39 | E16: 3.53 | F16: 3.45 | G16: 3.38 | H16: 3.4 | M16: =AVERAGE(D16:L16) | N16: =M16/5 | O16: =(M16-1)/4 | P16: 0.6862 | Q16: =IF(ABS(N16-P16)<=0.00105,"일치","불일치") | R16: =IF(ABS(O16-P16)<=0.0013,"일치","불일치")
A17: 2025 | B17: 수혜 | C17: Q16 | D17: 3.56 | E17: 3.61 | F17: 3.88 | G17: 3.8 | M17: =AVERAGE(D17:L17) | N17: =M17/5 | O17: =(M17-1)/4 | P17: 0.6779 | Q17: =IF(ABS(N17-P17)<=0.00105,"일치","불일치") | R17: =IF(ABS(O17-P17)<=0.0013,"일치","불일치")
A18: 2025 | B18: 일반 | C18: Q16 | D18: 3.42 | E18: 3.46 | F18: 3.64 | G18: 3.62 | M18: =AVERAGE(D18:L18) | N18: =M18/5 | O18: =(M18-1)/4 | P18: 0.634 | Q18: =IF(ABS(N18-P18)<=0.00105,"일치","불일치") | R18: =IF(ABS(O18-P18)<=0.0013,"일치","불일치")
A20: 결론: 2023·2024년은 ‘평균÷5’, 2025년은 ‘(평균−1)÷4’로 5점척도를 0~1로 바꾼 뒤 블록 배점을 곱함. 블록 안 문항은 동일가중(단순평균).
A22: 문17 노사협력 프로그램(13점) — 후보식 비교
A23: 연도 | B23: 집단 | D23: 시행률1 | E23: 시행률2 | F23: 시행률3 | G23: 시행률4 | H23: 시행률5 | I23: 활성1 | J23: 활성2 | K23: 활성3 | L23: 활성4 | M23: 활성5 | N23: (미시행1·시행a)/5 | O23: 시행률평균 | P23: 공식값 | Q23: 후보1 판정 | R23: 후보2 판정
A24: 2023 | B24: 수혜 | D24: 0.154 | E24: 0.485 | F24: 0.39 | G24: 0.592 | H24: 0.136 | I24: 3.52 | J24: 3.51 | K24: 3.53 | L24: 3.71 | M24: 3.59 | N24: =SUMPRODUCT(1-D24:H24+D24:H24*I24:M24)/25 | O24: =AVERAGE(D24:H24) | P24: 0.3818 | Q24: =IF(ABS(N24-P24)<=0.0007,"일치","불일치") | R24: =IF(ABS(O24-P24)<=0.0007,"일치","불일치")
A25: 2023 | B25: 일반 | D25: 0.158 | E25: 0.396 | F25: 0.311 | G25: 0.531 | H25: 0.109 | I25: 3.27 | J25: 3.5 | K25: 3.5 | L25: 3.6 | M25: 3.55 | N25: =SUMPRODUCT(1-D25:H25+D25:H25*I25:M25)/25 | O25: =AVERAGE(D25:H25) | P25: 0.3515 | Q25: =IF(ABS(N25-P25)<=0.0007,"일치","불일치") | R25: =IF(ABS(O25-P25)<=0.0007,"일치","불일치")
A26: 2024 | B26: 수혜 | D26: 0.173 | E26: 0.589 | F26: 0.456 | G26: 0.698 | H26: 0.145 | I26: 3.38 | J26: 3.57 | K26: 3.68 | L26: 3.72 | M26: 3.89 | N26: =SUMPRODUCT(1-D26:H26+D26:H26*I26:M26)/25 | O26: =AVERAGE(D26:H26) | P26: 0.3813 | Q26: =IF(ABS(N26-P26)<=0.0007,"일치","불일치") | R26: =IF(ABS(O26-P26)<=0.0007,"일치","불일치")
A27: 2024 | B27: 일반 | D27: 0.147 | E27: 0.47 | F27: 0.329 | G27: 0.588 | H27: 0.102 | I27: 3.22 | J27: 3.39 | K27: 3.43 | L27: 3.65 | M27: 3.65 | N27: =SUMPRODUCT(1-D27:H27+D27:H27*I27:M27)/25 | O27: =AVERAGE(D27:H27) | P27: 0.3011 | Q27: =IF(ABS(N27-P27)<=0.0007,"일치","불일치") | R27: =IF(ABS(O27-P27)<=0.0007,"일치","불일치")
A28: 2025 | B28: 수혜 | D28: 0.148 | E28: 0.506 | F28: 0.428 | G28: 0.643 | H28: 0.126 | I28: 3.29 | J28: 3.49 | K28: 3.69 | L28: 3.74 | M28: 3.57 | N28: =SUMPRODUCT(1-D28:H28+D28:H28*I28:M28)/25 | O28: =AVERAGE(D28:H28) | P28: 0.3836 | Q28: =IF(ABS(N28-P28)<=0.0007,"일치","불일치") | R28: =IF(ABS(O28-P28)<=0.0007,"일치","불일치")
A29: 2025 | B29: 일반 | D29: 0.088 | E29: 0.371 | F29: 0.294 | G29: 0.568 | H29: 0.102 | I29: 3.13 | J29: 3.43 | K29: 3.57 | L29: 3.61 | M29: 3.65 | N29: =SUMPRODUCT(1-D29:H29+D29:H29*I29:M29)/25 | O29: =AVERAGE(D29:H29) | P29: 0.2845 | Q29: =IF(ABS(N29-P29)<=0.0007,"일치","불일치") | R29: =IF(ABS(O29-P29)<=0.0007,"일치","불일치")
A30: → 2023은 (미시행=1, 시행=활성화)/5 식이 수혜·일반 모두 재현. 2025 일반은 시행률 평균과 일치. 2024 두 집단과 2025 수혜는 어떤 단순식으로도 재현 안 됨(원자료·결측처리 미공개).
A32: 문18 노사갈등(12점) — 1−평균발생률
A33: 연도 | B33: 집단 | D33: 파업% | E33: 손실% | F33: 고소% | G33: 해고% | N33: 1−평균발생률 | P33: 공식값 | Q33: 차이 | R33: 판정
A34: 2023 | B34: 수혜 | D34: 2 | E34: 3.3 | F34: 4 | G34: 1.5 | N34: =1-AVERAGE(D34:G34)/100 | P34: 0.9786 | Q34: =P34-N34 | R34: =IF(ABS(Q34)<=0.01,"근접(±0.01)","이상치")
A35: 2023 | B35: 일반 | D35: 2.3 | E35: 2.9 | F35: 4.7 | G35: 1.6 | N35: =1-AVERAGE(D35:G35)/100 | P35: 0.977 | Q35: =P35-N35 | R35: =IF(ABS(Q35)<=0.01,"근접(±0.01)","이상치")
A36: 2024 | B36: 수혜 | D36: 1.3 | E36: 1.6 | F36: 3.3 | G36: 2.2 | N36: =1-AVERAGE(D36:G36)/100 | P36: 0.6619 | Q36: =P36-N36 | R36: =IF(ABS(Q36)<=0.01,"근접(±0.01)","이상치")
A37: 2024 | B37: 일반 | D37: 2.3 | E37: 3.2 | F37: 3.2 | G37: 1.5 | N37: =1-AVERAGE(D37:G37)/100 | P37: 0.5087 | Q37: =P37-N37 | R37: =IF(ABS(Q37)<=0.01,"근접(±0.01)","이상치")
A38: 2025 | B38: 수혜 | D38: 0.2 | E38: 2 | F38: 3.1 | G38: 0.9 | N38: =1-AVERAGE(D38:G38)/100 | P38: 0.979 | Q38: =P38-N38 | R38: =IF(ABS(Q38)<=0.01,"근접(±0.01)","이상치")
A39: 2025 | B39: 일반 | D39: 0.9 | E39: 1.9 | F39: 1.9 | G39: 1.1 | N39: =1-AVERAGE(D39:G39)/100 | P39: 0.9808 | Q39: =P39-N39 | R39: =IF(ABS(Q39)<=0.01,"근접(±0.01)","이상치")
A40: → 2023 산정방식(p.242): 미발생 0·발생 −1로 재코딩 후 0~1 변환. 2023·2025는 ±0.006 근접(결측 분모 차이 추정), 2024 공표값만 크게 벗어남 → 2024(보정) 벤치마크 제공.

Sheet 모형설계
B1: 노사관계 진단 평가모형 설계서
B3: 1. 목적과 원칙
B4: · 노사발전재단 일터혁신지수 ‘노사관계’ 영역(100점)과 같은 문항·배점·변환식으로 채점해, 공식 벤치마크와 같은 잣대로 비교한다.
B5: · 공개 자료로 재현이 확인된 규칙(A)만 그대로 쓰고, 재현되지 않은 부분(B·C)은 근거를 밝히고 가장 근접한 대안을 쓴다.
B6: · 사업주·담당자 응답(재단 조사와 같은 응답주체)만 벤치마크와 비교하고, 근로자 응답은 따로 집계해 인식 차이를 본다.
B8: 2. 구조(36문항 → 7개 소분류 → 5개 중분류 → 100점)
B9: · 노사관계분위기 20 = 전반 인식(문16, 4문항) 10 + 노조·근로자대표 혁신 태도(문24, 5문항) 10
B10: · 노사협력 및 갈등 25 = 협력 프로그램(문17, 5종) 13 + 노사갈등(문18, 4종) 12
B11: · 정보공유와 의사소통 25 = 의사소통(문21, 5문항) + 경영정보 공유(문22, 4문항)
B12: · 고충처리 15 = 문19(4문항) · 노사협의회 15 = 문23(5문항)
B13: · 문항별 가중치(역산): 블록 안 동일가중 → 문16 2.50, 문24 2.00, 문17 2.60, 문18 3.00, 문21·22 2.78, 문19 3.75, 문23 3.00점/문항
B15: 3. 점수 변환식(역산 결과)
... B41: · 2026 「일터혁신 상생컨설팅 진단·평가 지표 개선방안 연구」 결과가 공개되면 문항·배점을 다시 검토해 [가중치]·[벤치마크] 시트만 갱신하면 된다.

Sheet 점수_응답자
A1: 응답자별 계산 시트 — 수정하지 마세요
A2: 노사협의회 제외 | C2: =AND(설문!$C$8="미설치",설문!$C$6="50인 미만",설문!$C$7="없음") | D2: 노사협의회 0점 처리 | E2: =AND(설문!$C$8="미설치",NOT($C$2))
A3: ID | B3: 구분 | C3: 배점 | D3: 설명 | E3: =설문!E12 | F3: =설문!F12 | G3: =설문!G12 | H3: =설문!H12 | I3: =설문!I12 | J3: =설문!J12 | K3: =설문!K12 | L3: =설문!L12 | ... BB3: =설문!BB12
A4: TYPE | B4: 응답자 유형 | E4: =IF(설문!E13="","",설문!E13) | F4: =IF(설문!F13="","",설문!F13) | G4: =IF(설문!G13="","",설문!G13) | H4: =IF(설문!H13="","",설문!H13) | I4: =IF(설문!I13="","",설문!I13) | J4: =IF(설문!J13="","",설문!J13) | K4: =IF(설문!K13="","",설문!K13) | L4: =IF(설문!L13="","",설문!L13) | ... BB4: =IF(설문!BB13="","",설문!BB13)
A5: VALID | B5: 유효 응답(1=집계) | E5: =IF(AND(E4<>"",COUNT(E8:E49)>0),1,0) | F5: =IF(AND(F4<>"",COUNT(F8:F49)>0),1,0) | G5: =IF(AND(G4<>"",COUNT(G8:G49)>0),1,0) | H5: =IF(AND(H4<>"",COUNT(H8:H49)>0),1,0) | I5: =IF(AND(I4<>"",COUNT(I8:I49)>0),1,0) | J5: =IF(AND(J4<>"",COUNT(J8:J49)>0),1,0) | K5: =IF(AND(K4<>"",COUNT(K8:K49)>0),1,0) | L5: =IF(AND(L4<>"",COUNT(L8:L49)>0),1,0) | ... BB5: =IF(AND(BB4<>"",COUNT(BB8:BB49)>0),1,0)
A7: ① RAW: 설문 응답을 숫자로 변환
A8: Q16_1 | B8: 5점척도 | E8: =IF(설문!E16="","",IFERROR(VALUE(설문!E16),"")) | F8: =IF(설문!F16="","",IFERROR(VALUE(설문!F16),"")) | G8: =IF(설문!G16="","",IFERROR(VALUE(설문!G16),"")) | H8: =IF(설문!H16="","",IFERROR(VALUE(설문!H16),"")) | I8: =IF(설문!I16="","",IFERROR(VALUE(설문!I16),"")) | J8: =IF(설문!J16="","",IFERROR(VALUE(설문!J16),"")) | K8: =IF(설문!K16="","",IFERROR(VALUE(설문!K16),"")) | L8: =IF(설문!L16="","",IFERROR(VALUE(설문!L16),"")) | ... BB8: =IF(설문!BB16="","",IFERROR(VALUE(설문!BB16),""))
A9: Q16_2 | B9: 5점척도 | E9: =IF(설문!E17="","",IFERROR(VALUE(설문!E17),"")) | F9: =IF(설문!F17="","",IFERROR(VALUE(설문!F17),"")) | G9: =IF(설문!G17="","",IFERROR(VALUE(설문!G17),"")) | H9: =IF(설문!H17="","",IFERROR(VALUE(설문!H17),"")) | I9: =IF(설문!I17="","",IFERROR(VALUE(설문!I17),"")) | J9: =IF(설문!J17="","",IFERROR(VALUE(설문!J17),"")) | K9: =IF(설문!K17="","",IFERROR(VALUE(설문!K17),"")) | L9: =IF(설문!L17="","",IFERROR(VALUE(설문!L17),"")) | ... BB9: =IF(설문!BB17="","",IFERROR(VALUE(설문!BB17),""))
A10: Q16_3 | B10: 5점척도 | E10: =IF(설문!E18="","",IFERROR(VALUE(설문!E18),"")) | F10: =IF(설문!F18="","",IFERROR(VALUE(설문!F18),"")) | G10: =IF(설문!G18="","",IFERROR(VALUE(설문!G18),"")) | H10: =IF(설문!H18="","",IFERROR(VALUE(설문!H18),"")) | I10: =IF(설문!I18="","",IFERROR(VALUE(설문!I18),"")) | J10: =IF(설문!J18="","",IFERROR(VALUE(설문!J18),"")) | K10: =IF(설문!K18="","",IFERROR(VALUE(설문!K18),"")) | L10: =IF(설문!L18="","",IFERROR(VALUE(설문!L18),"")) | ... BB10: =IF(설문!BB18="","",IFERROR(VALUE(설문!BB18),""))
A11: Q16_4 | B11: 5점척도 | E11: =IF(설문!E19="","",IFERROR(VALUE(설문!E19),"")) | F11: =IF(설문!F19="","",IFERROR(VALUE(설문!F19),"")) | G11: =IF(설문!G19="","",IFERROR(VALUE(설문!G19),"")) | H11: =IF(설문!H19="","",IFERROR(VALUE(설문!H19),"")) | I11: =IF(설문!I19="","",IFERROR(VALUE(설문!I19),"")) | J11: =IF(설문!J19="","",IFERROR(VALUE(설문!J19),"")) | K11: =IF(설문!K19="","",IFERROR(VALUE(설문!K19),"")) | L11: =IF(설문!L19="","",IFERROR(VALUE(설문!L19),"")) | ... BB11: =IF(설문!BB19="","",IFERROR(VALUE(설문!BB19),""))
A12: Q17_1 | B12: 시행=1 | E12: =IF(설문!E21="","",IF(설문!E21="시행",1,0)) | F12: =IF(설문!F21="","",IF(설문!F21="시행",1,0)) | G12: =IF(설문!G21="","",IF(설문!G21="시행",1,0)) | H12: =IF(설문!H21="","",IF(설문!H21="시행",1,0)) | I12: =IF(설문!I21="","",IF(설문!I21="시행",1,0)) | J12: =IF(설문!J21="","",IF(설문!J21="시행",1,0)) | K12: =IF(설문!K21="","",IF(설문!K21="시행",1,0)) | L12: =IF(설문!L21="","",IF(설문!L21="시행",1,0)) | ... BB12: =IF(설문!BB21="","",IF(설문!BB21="시행",1,0))
A13: Q17_1A | B13: 활성화 1~5 | E13: =IF(설문!E22="","",IFERROR(VALUE(설문!E22),"")) | F13: =IF(설문!F22="","",IFERROR(VALUE(설문!F22),"")) | G13: =IF(설문!G22="","",IFERROR(VALUE(설문!G22),"")) | H13: =IF(설문!H22="","",IFERROR(VALUE(설문!H22),"")) | I13: =IF(설문!I22="","",IFERROR(VALUE(설문!I22),"")) | J13: =IF(설문!J22="","",IFERROR(VALUE(설문!J22),"")) | K13: =IF(설문!K22="","",IFERROR(VALUE(설문!K22),"")) | L13: =IF(설문!L22="","",IFERROR(VALUE(설문!L22),"")) | ... BB13: =IF(설문!BB22="","",IFERROR(VALUE(설문!BB22),""))
A14: Q17_2 | B14: 시행=1 | E14: =IF(설문!E23="","",IF(설문!E23="시행",1,0)) | F14: =IF(설문!F23="","",IF(설문!F23="시행",1,0)) | G14: =IF(설문!G23="","",IF(설문!G23="시행",1,0)) | H14: =IF(설문!H23="","",IF(설문!H23="시행",1,0)) | I14: =IF(설문!I23="","",IF(설문!I23="시행",1,0)) | J14: =IF(설문!J23="","",IF(설문!J23="시행",1,0)) | K14: =IF(설문!K23="","",IF(설문!K23="시행",1,0)) | L14: =IF(설문!L23="","",IF(설문!L23="시행",1,0)) | ... BB14: =IF(설문!BB23="","",IF(설문!BB23="시행",1,0))
A15: Q17_2A | B15: 활성화 1~5 | E15: =IF(설문!E24="","",IFERROR(VALUE(설문!E24),"")) | F15: =IF(설문!F24="","",IFERROR(VALUE(설문!F24),"")) | G15: =IF(설문!G24="","",IFERROR(VALUE(설문!G24),"")) | H15: =IF(설문!H24="","",IFERROR(VALUE(설문!H24),"")) | I15: =IF(설문!I24="","",IFERROR(VALUE(설문!I24),"")) | J15: =IF(설문!J24="","",IFERROR(VALUE(설문!J24),"")) | K15: =IF(설문!K24="","",IFERROR(VALUE(설문!K24),"")) | L15: =IF(설문!L24="","",IFERROR(VALUE(설문!L24),"")) | ... BB15: =IF(설문!BB24="","",IFERROR(VALUE(설문!BB24),""))
A16: Q17_3 | B16: 시행=1 | E16: =IF(설문!E25="","",IF(설문!E25="시행",1,0)) | F16: =IF(설문!F25="","",IF(설문!F25="시행",1,0)) | G16: =IF(설문!G25="","",IF(설문!G25="시행",1,0)) | H16: =IF(설문!H25="","",IF(설문!H25="시행",1,0)) | I16: =IF(설문!I25="","",IF(설문!I25="시행",1,0)) | J16: =IF(설문!J25="","",IF(설문!J25="시행",1,0)) | K16: =IF(설문!K25="","",IF(설문!K25="시행",1,0)) | L16: =IF(설문!L25="","",IF(설문!L25="시행",1,0)) | ... BB16: =IF(설문!BB25="","",IF(설문!BB25="시행",1,0))
A17: Q17_3A | B17: 활성화 1~5 | E17: =IF(설문!E26="","",IFERROR(VALUE(설문!E26),"")) | F17: =IF(설문!F26="","",IFERROR(VALUE(설문!F26),"")) | G17: =IF(설문!G26="","",IFERROR(VALUE(설문!G26),"")) | H17: =IF(설문!H26="","",IFERROR(VALUE(설문!H26),"")) | I17: =IF(설문!I26="","",IFERROR(VALUE(설문!I26),"")) | J17: =IF(설문!J26="","",IFERROR(VALUE(설문!J26),"")) | K17: =IF(설문!K26="","",IFERROR(VALUE(설문!K26),"")) | L17: =IF(설문!L26="","",IFERROR(VALUE(설문!L26),"")) | ... BB17: =IF(설문!BB26="","",IFERROR(VALUE(설문!BB26),""))
A18: Q17_4 | B18: 시행=1 | E18: =IF(설문!E27="","",IF(설문!E27="시행",1,0)) | F18: =IF(설문!F27="","",IF(설문!F27="시행",1,0)) | G18: =IF(설문!G27="","",IF(설문!G27="시행",1,0)) | H18: =IF(설문!H27="","",IF(설문!H27="시행",1,0)) | I18: =IF(설문!I27="","",IF(설문!I27="시행",1,0)) | J18: =IF(설문!J27="","",IF(설문!J27="시행",1,0)) | K18: =IF(설문!K27="","",IF(설문!K27="시행",1,0)) | L18: =IF(설문!L27="","",IF(설문!L27="시행",1,0)) | ... BB18: =IF(설문!BB27="","",IF(설문!BB27="시행",1,0))
A19: Q17_4A | B19: 활성화 1~5 | E19: =IF(설문!E28="","",IFERROR(VALUE(설문!E28),"")) | F19: =IF(설문!F28="","",IFERROR(VALUE(설문!F28),"")) | G19: =IF(설문!G28="","",IFERROR(VALUE(설문!G28),"")) | H19: =IF(설문!H28="","",IFERROR(VALUE(설문!H28),"")) | I19: =IF(설문!I28="","",IFERROR(VALUE(설문!I28),"")) | J19: =IF(설문!J28="","",IFERROR(VALUE(설문!J28),"")) | K19: =IF(설문!K28="","",IFERROR(VALUE(설문!K28),"")) | L19: =IF(설문!L28="","",IFERROR(VALUE(설문!L28),"")) | ... BB19: =IF(설문!BB28="","",IFERROR(VALUE(설문!BB28),""))
A20: Q17_5 | B20: 시행=1 | E20: =IF(설문!E29="","",IF(설문!E29="시행",1,0)) | F20: =IF(설문!F29="","",IF(설문!F29="시행",1,0)) | G20: =IF(설문!G29="","",IF(설문!G29="시행",1,0)) | H20: =IF(설문!H29="","",IF(설문!H29="시행",1,0)) | I20: =IF(설문!I29="","",IF(설문!I29="시행",1,0)) | J20: =IF(설문!J29="","",IF(설문!J29="시행",1,0)) | K20: =IF(설문!K29="","",IF(설문!K29="시행",1,0)) | L20: =IF(설문!L29="","",IF(설문!L29="시행",1,0)) | ... BB20: =IF(설문!BB29="","",IF(설문!BB29="시행",1,0))
A21: Q17_5A | B21: 활성화 1~5 | E21: =IF(설문!E30="","",IFERROR(VALUE(설문!E30),"")) | F21: =IF(설문!F30="","",IFERROR(VALUE(설문!F30),"")) | G21: =IF(설문!G30="","",IFERROR(VALUE(설문!G30),"")) | H21: =IF(설문!H30="","",IFERROR(VALUE(설문!H30),"")) | I21: =IF(설문!I30="","",IFERROR(VALUE(설문!I30),"")) | J21: =IF(설문!J30="","",IFERROR(VALUE(설문!J30),"")) | K21: =IF(설문!K30="","",IFERROR(VALUE(설문!K30),"")) | L21: =IF(설문!L30="","",IFERROR(VALUE(설문!L30),"")) | ... BB21: =IF(설문!BB30="","",IFERROR(VALUE(설문!BB30),""))
A22: Q18_1 | B22: 발생=1 | E22: =IF(설문!E32="","",IF(설문!E32="발생",1,0)) | F22: =IF(설문!F32="","",IF(설문!F32="발생",1,0)) | G22: =IF(설문!G32="","",IF(설문!G32="발생",1,0)) | H22: =IF(설문!H32="","",IF(설문!H32="발생",1,0)) | I22: =IF(설문!I32="","",IF(설문!I32="발생",1,0)) | J22: =IF(설문!J32="","",IF(설문!J32="발생",1,0)) | K22: =IF(설문!K32="","",IF(설문!K32="발생",1,0)) | L22: =IF(설문!L32="","",IF(설문!L32="발생",1,0)) | ... BB22: =IF(설문!BB32="","",IF(설문!BB32="발생",1,0))
A23: Q18_2 | B23: 발생=1 | E23: =IF(설문!E33="","",IF(설문!E33="발생",1,0)) | F23: =IF(설문!F33="","",IF(설문!F33="발생",1,0)) | G23: =IF(설문!G33="","",IF(설문!G33="발생",1,0)) | H23: =IF(설문!H33="","",IF(설문!H33="발생",1,0)) | I23: =IF(설문!I33="","",IF(설문!I33="발생",1,0)) | J23: =IF(설문!J33="","",IF(설문!J33="발생",1,0)) | K23: =IF(설문!K33="","",IF(설문!K33="발생",1,0)) | L23: =IF(설문!L33="","",IF(설문!L33="발생",1,0)) | ... BB23: =IF(설문!BB33="","",IF(설문!BB33="발생",1,0))
A24: Q18_3 | B24: 발생=1 | E24: =IF(설문!E34="","",IF(설문!E34="발생",1,0)) | F24: =IF(설문!F34="","",IF(설문!F34="발생",1,0)) | G24: =IF(설문!G34="","",IF(설문!G34="발생",1,0)) | H24: =IF(설문!H34="","",IF(설문!H34="발생",1,0)) | I24: =IF(설문!I34="","",IF(설문!I34="발생",1,0)) | J24: =IF(설문!J34="","",IF(설문!J34="발생",1,0)) | K24: =IF(설문!K34="","",IF(설문!K34="발생",1,0)) | L24: =IF(설문!L34="","",IF(설문!L34="발생",1,0)) | ... BB24: =IF(설문!BB34="","",IF(설문!BB34="발생",1,0))
A25: Q18_4 | B25: 발생=1 | E25: =IF(설문!E35="","",IF(설문!E35="발생",1,0)) | F25: =IF(설문!F35="","",IF(설문!F35="발생",1,0)) | G25: =IF(설문!G35="","",IF(설문!G35="발생",1,0)) | H25: =IF(설문!H35="","",IF(설문!H35="발생",1,0)) | I25: =IF(설문!I35="","",IF(설문!I35="발생",1,0)) | J25: =IF(설문!J35="","",IF(설문!J35="발생",1,0)) | K25: =IF(설문!K35="","",IF(설문!K35="발생",1,0)) | L25: =IF(설문!L35="","",IF(설문!L35="발생",1,0)) | ... BB25: =IF(설문!BB35="","",IF(설문!BB35="발생",1,0))
A26: Q19_1 | B26: 5점척도 | E26: =IF(설문!E37="","",IFERROR(VALUE(설문!E37),"")) | F26: =IF(설문!F37="","",IFERROR(VALUE(설문!F37),"")) | G26: =IF(설문!G37="","",IFERROR(VALUE(설문!G37),"")) | H26: =IF(설문!H37="","",IFERROR(VALUE(설문!H37),"")) | I26: =IF(설문!I37="","",IFERROR(VALUE(설문!I37),"")) | J26: =IF(설문!J37="","",IFERROR(VALUE(설문!J37),"")) | K26: =IF(설문!K37="","",IFERROR(VALUE(설문!K37),"")) | L26: =IF(설문!L37="","",IFERROR(VALUE(설문!L37),"")) | ... BB26: =IF(설문!BB37="","",IFERROR(VALUE(설문!BB37),""))
A27: Q19_2 | B27: 5점척도 | E27: =IF(설문!E38="","",IFERROR(VALUE(설문!E38),"")) | F27: =IF(설문!F38="","",IFERROR(VALUE(설문!F38),"")) | G27: =IF(설문!G38="","",IFERROR(VALUE(설문!G38),"")) | H27: =IF(설문!H38="","",IFERROR(VALUE(설문!H38),"")) | I27: =IF(설문!I38="","",IFERROR(VALUE(설문!I38),"")) | J27: =IF(설문!J38="","",IFERROR(VALUE(설문!J38),"")) | K27: =IF(설문!K38="","",IFERROR(VALUE(설문!K38),"")) | L27: =IF(설문!L38="","",IFERROR(VALUE(설문!L38),"")) | ... BB27: =IF(설문!BB38="","",IFERROR(VALUE(설문!BB38),""))
A28: Q19_3 | B28: 5점척도 | E28: =IF(설문!E39="","",IFERROR(VALUE(설문!E39),"")) | F28: =IF(설문!F39="","",IFERROR(VALUE(설문!F39),"")) | G28: =IF(설문!G39="","",IFERROR(VALUE(설문!G39),"")) | H28: =IF(설문!H39="","",IFERROR(VALUE(설문!H39),"")) | I28: =IF(설문!I39="","",IFERROR(VALUE(설문!I39),"")) | J28: =IF(설문!J39="","",IFERROR(VALUE(설문!J39),"")) | K28: =IF(설문!K39="","",IFERROR(VALUE(설문!K39),"")) | L28: =IF(설문!L39="","",IFERROR(VALUE(설문!L39),"")) | ... BB28: =IF(설문!BB39="","",IFERROR(VALUE(설문!BB39),""))
A29: Q19_4 | B29: 5점척도 | E29: =IF(설문!E40="","",IFERROR(VALUE(설문!E40),"")) | F29: =IF(설문!F40="","",IFERROR(VALUE(설문!F40),"")) | G29: =IF(설문!G40="","",IFERROR(VALUE(설문!G40),"")) | H29: =IF(설문!H40="","",IFERROR(VALUE(설문!H40),"")) | I29: =IF(설문!I40="","",IFERROR(VALUE(설문!I40),"")) | J29: =IF(설문!J40="","",IFERROR(VALUE(설문!J40),"")) | K29: =IF(설문!K40="","",IFERROR(VALUE(설문!K40),"")) | L29: =IF(설문!L40="","",IFERROR(VALUE(설문!L40),"")) | ... BB29: =IF(설문!BB40="","",IFERROR(VALUE(설문!BB40),""))
A30: Q20 | B30: 참고 1~5 | E30: =IF(설문!E42="","",IFERROR(VALUE(설문!E42),"")) | F30: =IF(설문!F42="","",IFERROR(VALUE(설문!F42),"")) | G30: =IF(설문!G42="","",IFERROR(VALUE(설문!G42),"")) | H30: =IF(설문!H42="","",IFERROR(VALUE(설문!H42),"")) | I30: =IF(설문!I42="","",IFERROR(VALUE(설문!I42),"")) | J30: =IF(설문!J42="","",IFERROR(VALUE(설문!J42),"")) | K30: =IF(설문!K42="","",IFERROR(VALUE(설문!K42),"")) | L30: =IF(설문!L42="","",IFERROR(VALUE(설문!L42),"")) | ... BB30: =IF(설문!BB42="","",IFERROR(VALUE(설문!BB42),""))
A31: Q21_1 | B31: 5점척도 | E31: =IF(설문!E44="","",IFERROR(VALUE(설문!E44),"")) | F31: =IF(설문!F44="","",IFERROR(VALUE(설문!F44),"")) | G31: =IF(설문!G44="","",IFERROR(VALUE(설문!G44),"")) | H31: =IF(설문!H44="","",IFERROR(VALUE(설문!H44),"")) | I31: =IF(설문!I44="","",IFERROR(VALUE(설문!I44),"")) | J31: =IF(설문!J44="","",IFERROR(VALUE(설문!J44),"")) | K31: =IF(설문!K44="","",IFERROR(VALUE(설문!K44),"")) | L31: =IF(설문!L44="","",IFERROR(VALUE(설문!L44),"")) | ... BB31: =IF(설문!BB44="","",IFERROR(VALUE(설문!BB44),""))
A32: Q21_2 | B32: 5점척도 | E32: =IF(설문!E45="","",IFERROR(VALUE(설문!E45),"")) | F32: =IF(설문!F45="","",IFERROR(VALUE(설문!F45),"")) | G32: =IF(설문!G45="","",IFERROR(VALUE(설문!G45),"")) | H32: =IF(설문!H45="","",IFERROR(VALUE(설문!H45),"")) | I32: =IF(설문!I45="","",IFERROR(VALUE(설문!I45),"")) | J32: =IF(설문!J45="","",IFERROR(VALUE(설문!J45),"")) | K32: =IF(설문!K45="","",IFERROR(VALUE(설문!K45),"")) | L32: =IF(설문!L45="","",IFERROR(VALUE(설문!L45),"")) | ... BB32: =IF(설문!BB45="","",IFERROR(VALUE(설문!BB45),""))
A33: Q21_3 | B33: 5점척도 | E33: =IF(설문!E46="","",IFERROR(VALUE(설문!E46),"")) | F33: =IF(설문!F46="","",IFERROR(VALUE(설문!F46),"")) | G33: =IF(설문!G46="","",IFERROR(VALUE(설문!G46),"")) | H33: =IF(설문!H46="","",IFERROR(VALUE(설문!H46),"")) | I33: =IF(설문!I46="","",IFERROR(VALUE(설문!I46),"")) | J33: =IF(설문!J46="","",IFERROR(VALUE(설문!J46),"")) | K33: =IF(설문!K46="","",IFERROR(VALUE(설문!K46),"")) | L33: =IF(설문!L46="","",IFERROR(VALUE(설문!L46),"")) | ... BB33: =IF(설문!BB46="","",IFERROR(VALUE(설문!BB46),""))
A34: Q21_4 | B34: 5점척도 | E34: =IF(설문!E47="","",IFERROR(VALUE(설문!E47),"")) | F34: =IF(설문!F47="","",IFERROR(VALUE(설문!F47),"")) | G34: =IF(설문!G47="","",IFERROR(VALUE(설문!G47),"")) | H34: =IF(설문!H47="","",IFERROR(VALUE(설문!H47),"")) | I34: =IF(설문!I47="","",IFERROR(VALUE(설문!I47),"")) | J34: =IF(설문!J47="","",IFERROR(VALUE(설문!J47),"")) | K34: =IF(설문!K47="","",IFERROR(VALUE(설문!K47),"")) | L34: =IF(설문!L47="","",IFERROR(VALUE(설문!L47),"")) | ... BB34: =IF(설문!BB47="","",IFERROR(VALUE(설문!BB47),""))
A35: Q21_5 | B35: 5점척도 | E35: =IF(설문!E48="","",IFERROR(VALUE(설문!E48),"")) | F35: =IF(설문!F48="","",IFERROR(VALUE(설문!F48),"")) | G35: =IF(설문!G48="","",IFERROR(VALUE(설문!G48),"")) | H35: =IF(설문!H48="","",IFERROR(VALUE(설문!H48),"")) | I35: =IF(설문!I48="","",IFERROR(VALUE(설문!I48),"")) | J35: =IF(설문!J48="","",IFERROR(VALUE(설문!J48),"")) | K35: =IF(설문!K48="","",IFERROR(VALUE(설문!K48),"")) | L35: =IF(설문!L48="","",IFERROR(VALUE(설문!L48),"")) | ... BB35: =IF(설문!BB48="","",IFERROR(VALUE(설문!BB48),""))
A36: Q22_1 | B36: 5점척도 | E36: =IF(설문!E50="","",IFERROR(VALUE(설문!E50),"")) | F36: =IF(설문!F50="","",IFERROR(VALUE(설문!F50),"")) | G36: =IF(설문!G50="","",IFERROR(VALUE(설문!G50),"")) | H36: =IF(설문!H50="","",IFERROR(VALUE(설문!H50),"")) | I36: =IF(설문!I50="","",IFERROR(VALUE(설문!I50),"")) | J36: =IF(설문!J50="","",IFERROR(VALUE(설문!J50),"")) | K36: =IF(설문!K50="","",IFERROR(VALUE(설문!K50),"")) | L36: =IF(설문!L50="","",IFERROR(VALUE(설문!L50),"")) | ... BB36: =IF(설문!BB50="","",IFERROR(VALUE(설문!BB50),""))
A37: Q22_2 | B37: 5점척도 | E37: =IF(설문!E51="","",IFERROR(VALUE(설문!E51),"")) | F37: =IF(설문!F51="","",IFERROR(VALUE(설문!F51),"")) | G37: =IF(설문!G51="","",IFERROR(VALUE(설문!G51),"")) | H37: =IF(설문!H51="","",IFERROR(VALUE(설문!H51),"")) | I37: =IF(설문!I51="","",IFERROR(VALUE(설문!I51),"")) | J37: =IF(설문!J51="","",IFERROR(VALUE(설문!J51),"")) | K37: =IF(설문!K51="","",IFERROR(VALUE(설문!K51),"")) | L37: =IF(설문!L51="","",IFERROR(VALUE(설문!L51),"")) | ... BB37: =IF(설문!BB51="","",IFERROR(VALUE(설문!BB51),""))
A38: Q22_3 | B38: 5점척도 | E38: =IF(설문!E52="","",IFERROR(VALUE(설문!E52),"")) | F38: =IF(설문!F52="","",IFERROR(VALUE(설문!F52),"")) | G38: =IF(설문!G52="","",IFERROR(VALUE(설문!G52),"")) | H38: =IF(설문!H52="","",IFERROR(VALUE(설문!H52),"")) | I38: =IF(설문!I52="","",IFERROR(VALUE(설문!I52),"")) | J38: =IF(설문!J52="","",IFERROR(VALUE(설문!J52),"")) | K38: =IF(설문!K52="","",IFERROR(VALUE(설문!K52),"")) | L38: =IF(설문!L52="","",IFERROR(VALUE(설문!L52),"")) | ... BB38: =IF(설문!BB52="","",IFERROR(VALUE(설문!BB52),""))
A39: Q22_4 | B39: 5점척도 | E39: =IF(설문!E53="","",IFERROR(VALUE(설문!E53),"")) | F39: =IF(설문!F53="","",IFERROR(VALUE(설문!F53),"")) | G39: =IF(설문!G53="","",IFERROR(VALUE(설문!G53),"")) | H39: =IF(설문!H53="","",IFERROR(VALUE(설문!H53),"")) | I39: =IF(설문!I53="","",IFERROR(VALUE(설문!I53),"")) | J39: =IF(설문!J53="","",IFERROR(VALUE(설문!J53),"")) | K39: =IF(설문!K53="","",IFERROR(VALUE(설문!K53),"")) | L39: =IF(설문!L53="","",IFERROR(VALUE(설문!L53),"")) | ... BB39: =IF(설문!BB53="","",IFERROR(VALUE(설문!BB53),""))
A40: Q23_1 | B40: 5점척도 | E40: =IF(설문!E55="","",IFERROR(VALUE(설문!E55),"")) | F40: =IF(설문!F55="","",IFERROR(VALUE(설문!F55),"")) | G40: =IF(설문!G55="","",IFERROR(VALUE(설문!G55),"")) | H40: =IF(설문!H55="","",IFERROR(VALUE(설문!H55),"")) | I40: =IF(설문!I55="","",IFERROR(VALUE(설문!I55),"")) | J40: =IF(설문!J55="","",IFERROR(VALUE(설문!J55),"")) | K40: =IF(설문!K55="","",IFERROR(VALUE(설문!K55),"")) | L40: =IF(설문!L55="","",IFERROR(VALUE(설문!L55),"")) | ... BB40: =IF(설문!BB55="","",IFERROR(VALUE(설문!BB55),""))
A41: Q23_2 | B41: 5점척도 | E41: =IF(설문!E56="","",IFERROR(VALUE(설문!E56),"")) | F41: =IF(설문!F56="","",IFERROR(VALUE(설문!F56),"")) | G41: =IF(설문!G56="","",IFERROR(VALUE(설문!G56),"")) | H41: =IF(설문!H56="","",IFERROR(VALUE(설문!H56),"")) | I41: =IF(설문!I56="","",IFERROR(VALUE(설문!I56),"")) | J41: =IF(설문!J56="","",IFERROR(VALUE(설문!J56),"")) | K41: =IF(설문!K56="","",IFERROR(VALUE(설문!K56),"")) | L41: =IF(설문!L56="","",IFERROR(VALUE(설문!L56),"")) | ... BB41: =IF(설문!BB56="","",IFERROR(VALUE(설문!BB56),""))
...
